 
No internet connection... Press any key to resume ... 
Traceback (most recent call last):
  File "inputs.py", line 149, in <module>
    scenarios_ = scenarios_[:1]
TypeError: unhashable type: 'slice'
COUNTRIES=AUT
SCENARIOS=high-vaccination low-vaccination no-vaccination scenario-comparison
 
 
############################################################################
RUNNING ANALYSIS (WEB)
############################################################################
 
 
[jupytext] Reading web-run-sim.ipynb in format ipynb
[jupytext] Loading 'web-run-sim.py'
[jupytext] Updating 'web-run-sim.ipynb'
[jupytext] Updating 'web-run-sim.py'
[jupytext] Reading web-meta.ipynb in format ipynb
[jupytext] Loading 'web-meta.py'
[jupytext] Updating 'web-meta.ipynb'
[jupytext] Updating 'web-meta.py'
[jupytext] Reading web-index.ipynb in format ipynb
[jupytext] Loading 'web-index.py'
[jupytext] Updating 'web-index.ipynb'
[jupytext] Updating 'web-index.py'
[jupytext] Reading web-country-scen.ipynb in format ipynb
[jupytext] Updating 'web-country-scen.py'
[jupytext] Reading web-country-comp.ipynb in format ipynb
[jupytext] Loading 'web-country-comp.py'
[jupytext] Updating 'web-country-comp.ipynb'
[jupytext] Updating 'web-country-comp.py'
 
RUNNING ANALYSIS FOR COUNTRY: AUT...
 
Input Notebook:  ./web-run-sim_.ipynb
Output Notebook: ./web-run-sim_.ipynb
Generating grammar tables from /home/jb/.local/lib/python3.7/site-packages/blib2to3/Grammar.txt
Writing grammar tables to /home/jb/.cache/black/20.8b1/Grammar3.7.3.final.0.pickle
Writing failed: [Errno 2] No such file or directory: '/home/jb/.cache/black/20.8b1/tmpwggi3daw'
Generating grammar tables from /home/jb/.local/lib/python3.7/site-packages/blib2to3/PatternGrammar.txt
Writing grammar tables to /home/jb/.cache/black/20.8b1/PatternGrammar3.7.3.final.0.pickle
Writing failed: [Errno 2] No such file or directory: '/home/jb/.cache/black/20.8b1/tmpyb5o41h9'
Executing:   0%|          | 0/17 [00:00<?, ?cell/s]Executing notebook with kernel: python3
Executing:   6%|▌         | 1/17 [00:00<00:13,  1.17cell/s]Executing:  35%|███▌      | 6/17 [00:01<00:06,  1.64cell/s]Executing:  35%|███▌      | 6/17 [00:02<00:04,  2.70cell/s]
Traceback (most recent call last):
  File "/home/jb/.local/bin/papermill", line 8, in <module>
    sys.exit(papermill())
  File "/home/jb/.local/lib/python3.7/site-packages/click/core.py", line 1137, in __call__
    return self.main(*args, **kwargs)
  File "/home/jb/.local/lib/python3.7/site-packages/click/core.py", line 1062, in main
    rv = self.invoke(ctx)
  File "/home/jb/.local/lib/python3.7/site-packages/click/core.py", line 1404, in invoke
    return ctx.invoke(self.callback, **ctx.params)
  File "/home/jb/.local/lib/python3.7/site-packages/click/core.py", line 763, in invoke
    return __callback(*args, **kwargs)
  File "/home/jb/.local/lib/python3.7/site-packages/click/decorators.py", line 26, in new_func
    return f(get_current_context(), *args, **kwargs)
  File "/home/jb/.local/lib/python3.7/site-packages/papermill/cli.py", line 267, in papermill
    execution_timeout=execution_timeout,
  File "/home/jb/.local/lib/python3.7/site-packages/papermill/execute.py", line 122, in execute_notebook
    raise_for_execution_errors(nb, output_path)
  File "/home/jb/.local/lib/python3.7/site-packages/papermill/execute.py", line 234, in raise_for_execution_errors
    raise error
papermill.exceptions.PapermillExecutionError: 
---------------------------------------------------------------------------
Exception encountered at "In [5]":
---------------------------------------------------------------------------
TypeError                                 Traceback (most recent call last)
<ipython-input-5-77a8edef756d> in <module>
----> 1 import simulation
      2 
      3 import ccodes
      4 
      5 cname_f = ccodes.ct_codes[cname]

~/git/covid-19-sird/sim/output/src/simulation.py in <module>
     11 # run_model_set.cache_clear()
     12 
---> 13 import inputs
     14 
     15 

~/git/covid-19-sird/sim/output/src/inputs.py in <module>
    147 
    148 if dbg_scen:
--> 149     scenarios_ = scenarios_[:1]
    150 
    151 cc = ('{} '*len(countries_)).format(*countries_)

TypeError: unhashable type: 'slice'

[NbConvertApp] Converting notebook ./web-run-sim_.ipynb to html
[NbConvertApp] Writing 572038 bytes to web-run-sim_.html
 
SCENARIO: high-vaccination...
 
Input Notebook:  ./web-country-scen_.ipynb
Output Notebook: ./web-country-scen_.ipynb
Generating grammar tables from /home/jb/.local/lib/python3.7/site-packages/blib2to3/Grammar.txt
Writing grammar tables to /home/jb/.cache/black/20.8b1/Grammar3.7.3.final.0.pickle
Writing failed: [Errno 2] No such file or directory: '/home/jb/.cache/black/20.8b1/tmp6awm_czh'
Generating grammar tables from /home/jb/.local/lib/python3.7/site-packages/blib2to3/PatternGrammar.txt
Writing grammar tables to /home/jb/.cache/black/20.8b1/PatternGrammar3.7.3.final.0.pickle
Writing failed: [Errno 2] No such file or directory: '/home/jb/.cache/black/20.8b1/tmpvo_vy_ru'
Executing:   0%|          | 0/41 [00:00<?, ?cell/s]Executing notebook with kernel: python3
Executing:   2%|▏         | 1/41 [00:00<00:38,  1.05cell/s]Executing:   7%|▋         | 3/41 [00:01<00:26,  1.46cell/s]Executing:  12%|█▏        | 5/41 [00:01<00:17,  2.02cell/s]Executing:  17%|█▋        | 7/41 [00:01<00:13,  2.61cell/s]Executing:  22%|██▏       | 9/41 [00:01<00:09,  3.50cell/s]Executing:  27%|██▋       | 11/41 [00:01<00:06,  4.58cell/s]Executing:  32%|███▏      | 13/41 [00:02<00:07,  3.58cell/s]Executing:  37%|███▋      | 15/41 [00:02<00:05,  4.66cell/s]Executing:  41%|████▏     | 17/41 [00:02<00:04,  5.87cell/s]Executing:  46%|████▋     | 19/41 [00:02<00:03,  6.52cell/s]Executing:  46%|████▋     | 19/41 [00:04<00:04,  4.44cell/s]
Traceback (most recent call last):
  File "/home/jb/.local/bin/papermill", line 8, in <module>
    sys.exit(papermill())
  File "/home/jb/.local/lib/python3.7/site-packages/click/core.py", line 1137, in __call__
    return self.main(*args, **kwargs)
  File "/home/jb/.local/lib/python3.7/site-packages/click/core.py", line 1062, in main
    rv = self.invoke(ctx)
  File "/home/jb/.local/lib/python3.7/site-packages/click/core.py", line 1404, in invoke
    return ctx.invoke(self.callback, **ctx.params)
  File "/home/jb/.local/lib/python3.7/site-packages/click/core.py", line 763, in invoke
    return __callback(*args, **kwargs)
  File "/home/jb/.local/lib/python3.7/site-packages/click/decorators.py", line 26, in new_func
    return f(get_current_context(), *args, **kwargs)
  File "/home/jb/.local/lib/python3.7/site-packages/papermill/cli.py", line 267, in papermill
    execution_timeout=execution_timeout,
  File "/home/jb/.local/lib/python3.7/site-packages/papermill/execute.py", line 122, in execute_notebook
    raise_for_execution_errors(nb, output_path)
  File "/home/jb/.local/lib/python3.7/site-packages/papermill/execute.py", line 234, in raise_for_execution_errors
    raise error
papermill.exceptions.PapermillExecutionError: 
---------------------------------------------------------------------------
Exception encountered at "In [18]":
---------------------------------------------------------------------------
TypeError                                 Traceback (most recent call last)
<ipython-input-18-d2153f43af6d> in <module>
     20             # The protocol version used is detected automatically, so we do not
     21             # have to specify it.
---> 22             sim_Countries_cname = pickle.load(f)
     23 
     24 

~/git/covid-19-sird/sim/output/src/simulation.py in <module>
     11 # run_model_set.cache_clear()
     12 
---> 13 import inputs
     14 
     15 

~/git/covid-19-sird/sim/output/src/inputs.py in <module>
    147 
    148 if dbg_scen:
--> 149     scenarios_ = scenarios_[:1]
    150 
    151 cc = ('{} '*len(countries_)).format(*countries_)

TypeError: unhashable type: 'slice'

 
SCENARIO: low-vaccination...
 
Input Notebook:  ./web-country-scen_.ipynb
Output Notebook: ./web-country-scen_.ipynb
Generating grammar tables from /home/jb/.local/lib/python3.7/site-packages/blib2to3/Grammar.txt
Writing grammar tables to /home/jb/.cache/black/20.8b1/Grammar3.7.3.final.0.pickle
Writing failed: [Errno 2] No such file or directory: '/home/jb/.cache/black/20.8b1/tmpdz0rvoe0'
Generating grammar tables from /home/jb/.local/lib/python3.7/site-packages/blib2to3/PatternGrammar.txt
Writing grammar tables to /home/jb/.cache/black/20.8b1/PatternGrammar3.7.3.final.0.pickle
Writing failed: [Errno 2] No such file or directory: '/home/jb/.cache/black/20.8b1/tmp558z2i7q'
Executing:   0%|          | 0/41 [00:00<?, ?cell/s]Executing notebook with kernel: python3
Executing:   2%|▏         | 1/41 [00:00<00:36,  1.10cell/s]Executing:   7%|▋         | 3/41 [00:01<00:24,  1.53cell/s]Executing:  12%|█▏        | 5/41 [00:01<00:17,  2.10cell/s]Executing:  17%|█▋        | 7/41 [00:01<00:12,  2.71cell/s]Executing:  22%|██▏       | 9/41 [00:01<00:08,  3.62cell/s]Executing:  27%|██▋       | 11/41 [00:01<00:06,  4.73cell/s]Executing:  32%|███▏      | 13/41 [00:02<00:07,  3.61cell/s]Executing:  37%|███▋      | 15/41 [00:02<00:05,  4.73cell/s]Executing:  41%|████▏     | 17/41 [00:02<00:03,  6.03cell/s]Executing:  46%|████▋     | 19/41 [00:02<00:03,  6.84cell/s]Executing:  46%|████▋     | 19/41 [00:04<00:04,  4.47cell/s]
Traceback (most recent call last):
  File "/home/jb/.local/bin/papermill", line 8, in <module>
    sys.exit(papermill())
  File "/home/jb/.local/lib/python3.7/site-packages/click/core.py", line 1137, in __call__
    return self.main(*args, **kwargs)
  File "/home/jb/.local/lib/python3.7/site-packages/click/core.py", line 1062, in main
    rv = self.invoke(ctx)
  File "/home/jb/.local/lib/python3.7/site-packages/click/core.py", line 1404, in invoke
    return ctx.invoke(self.callback, **ctx.params)
  File "/home/jb/.local/lib/python3.7/site-packages/click/core.py", line 763, in invoke
    return __callback(*args, **kwargs)
  File "/home/jb/.local/lib/python3.7/site-packages/click/decorators.py", line 26, in new_func
    return f(get_current_context(), *args, **kwargs)
  File "/home/jb/.local/lib/python3.7/site-packages/papermill/cli.py", line 267, in papermill
    execution_timeout=execution_timeout,
  File "/home/jb/.local/lib/python3.7/site-packages/papermill/execute.py", line 122, in execute_notebook
    raise_for_execution_errors(nb, output_path)
  File "/home/jb/.local/lib/python3.7/site-packages/papermill/execute.py", line 234, in raise_for_execution_errors
    raise error
papermill.exceptions.PapermillExecutionError: 
---------------------------------------------------------------------------
Exception encountered at "In [18]":
---------------------------------------------------------------------------
TypeError                                 Traceback (most recent call last)
<ipython-input-18-d2153f43af6d> in <module>
     20             # The protocol version used is detected automatically, so we do not
     21             # have to specify it.
---> 22             sim_Countries_cname = pickle.load(f)
     23 
     24 

~/git/covid-19-sird/sim/output/src/simulation.py in <module>
     11 # run_model_set.cache_clear()
     12 
---> 13 import inputs
     14 
     15 

~/git/covid-19-sird/sim/output/src/inputs.py in <module>
    147 
    148 if dbg_scen:
--> 149     scenarios_ = scenarios_[:1]
    150 
    151 cc = ('{} '*len(countries_)).format(*countries_)

TypeError: unhashable type: 'slice'

 
SCENARIO: no-vaccination...
 
Input Notebook:  ./web-country-scen_.ipynb
Output Notebook: ./web-country-scen_.ipynb
Generating grammar tables from /home/jb/.local/lib/python3.7/site-packages/blib2to3/Grammar.txt
Writing grammar tables to /home/jb/.cache/black/20.8b1/Grammar3.7.3.final.0.pickle
Writing failed: [Errno 2] No such file or directory: '/home/jb/.cache/black/20.8b1/tmp3qltc11t'
Generating grammar tables from /home/jb/.local/lib/python3.7/site-packages/blib2to3/PatternGrammar.txt
Writing grammar tables to /home/jb/.cache/black/20.8b1/PatternGrammar3.7.3.final.0.pickle
Writing failed: [Errno 2] No such file or directory: '/home/jb/.cache/black/20.8b1/tmpujwwgxyh'
Executing:   0%|          | 0/41 [00:00<?, ?cell/s]Executing notebook with kernel: python3
Executing:   2%|▏         | 1/41 [00:00<00:35,  1.11cell/s]Executing:   7%|▋         | 3/41 [00:01<00:24,  1.54cell/s]Executing:  12%|█▏        | 5/41 [00:01<00:16,  2.12cell/s]Executing:  17%|█▋        | 7/41 [00:01<00:12,  2.73cell/s]Executing:  22%|██▏       | 9/41 [00:01<00:08,  3.64cell/s]Executing:  27%|██▋       | 11/41 [00:01<00:06,  4.73cell/s]Executing:  32%|███▏      | 13/41 [00:02<00:07,  3.69cell/s]Executing:  37%|███▋      | 15/41 [00:02<00:05,  4.83cell/s]Executing:  41%|████▏     | 17/41 [00:02<00:03,  6.16cell/s]Executing:  46%|████▋     | 19/41 [00:02<00:03,  6.92cell/s]Executing:  46%|████▋     | 19/41 [00:04<00:04,  4.47cell/s]
Traceback (most recent call last):
  File "/home/jb/.local/bin/papermill", line 8, in <module>
    sys.exit(papermill())
  File "/home/jb/.local/lib/python3.7/site-packages/click/core.py", line 1137, in __call__
    return self.main(*args, **kwargs)
  File "/home/jb/.local/lib/python3.7/site-packages/click/core.py", line 1062, in main
    rv = self.invoke(ctx)
  File "/home/jb/.local/lib/python3.7/site-packages/click/core.py", line 1404, in invoke
    return ctx.invoke(self.callback, **ctx.params)
  File "/home/jb/.local/lib/python3.7/site-packages/click/core.py", line 763, in invoke
    return __callback(*args, **kwargs)
  File "/home/jb/.local/lib/python3.7/site-packages/click/decorators.py", line 26, in new_func
    return f(get_current_context(), *args, **kwargs)
  File "/home/jb/.local/lib/python3.7/site-packages/papermill/cli.py", line 267, in papermill
    execution_timeout=execution_timeout,
  File "/home/jb/.local/lib/python3.7/site-packages/papermill/execute.py", line 122, in execute_notebook
    raise_for_execution_errors(nb, output_path)
  File "/home/jb/.local/lib/python3.7/site-packages/papermill/execute.py", line 234, in raise_for_execution_errors
    raise error
papermill.exceptions.PapermillExecutionError: 
---------------------------------------------------------------------------
Exception encountered at "In [18]":
---------------------------------------------------------------------------
TypeError                                 Traceback (most recent call last)
<ipython-input-18-d2153f43af6d> in <module>
     20             # The protocol version used is detected automatically, so we do not
     21             # have to specify it.
---> 22             sim_Countries_cname = pickle.load(f)
     23 
     24 

~/git/covid-19-sird/sim/output/src/simulation.py in <module>
     11 # run_model_set.cache_clear()
     12 
---> 13 import inputs
     14 
     15 

~/git/covid-19-sird/sim/output/src/inputs.py in <module>
    147 
    148 if dbg_scen:
--> 149     scenarios_ = scenarios_[:1]
    150 
    151 cc = ('{} '*len(countries_)).format(*countries_)

TypeError: unhashable type: 'slice'

 
SCENARIO: scenario-comparison...
 
Input Notebook:  ./web-country-scen_.ipynb
Output Notebook: ./web-country-scen_.ipynb
Generating grammar tables from /home/jb/.local/lib/python3.7/site-packages/blib2to3/Grammar.txt
Writing grammar tables to /home/jb/.cache/black/20.8b1/Grammar3.7.3.final.0.pickle
Writing failed: [Errno 2] No such file or directory: '/home/jb/.cache/black/20.8b1/tmpscejwu59'
Generating grammar tables from /home/jb/.local/lib/python3.7/site-packages/blib2to3/PatternGrammar.txt
Writing grammar tables to /home/jb/.cache/black/20.8b1/PatternGrammar3.7.3.final.0.pickle
Writing failed: [Errno 2] No such file or directory: '/home/jb/.cache/black/20.8b1/tmprhagdtci'
Executing:   0%|          | 0/41 [00:00<?, ?cell/s]Executing notebook with kernel: python3
Executing:   2%|▏         | 1/41 [00:00<00:36,  1.10cell/s]Executing:   7%|▋         | 3/41 [00:01<00:24,  1.53cell/s]Executing:  12%|█▏        | 5/41 [00:01<00:17,  2.10cell/s]Executing:  17%|█▋        | 7/41 [00:01<00:12,  2.68cell/s]Executing:  22%|██▏       | 9/41 [00:01<00:08,  3.56cell/s]Executing:  27%|██▋       | 11/41 [00:01<00:06,  4.63cell/s]Executing:  32%|███▏      | 13/41 [00:02<00:07,  3.57cell/s]Executing:  37%|███▋      | 15/41 [00:02<00:05,  4.68cell/s]Executing:  41%|████▏     | 17/41 [00:02<00:04,  5.98cell/s]Executing:  46%|████▋     | 19/41 [00:02<00:03,  6.80cell/s]Executing:  46%|████▋     | 19/41 [00:04<00:04,  4.47cell/s]
Traceback (most recent call last):
  File "/home/jb/.local/bin/papermill", line 8, in <module>
    sys.exit(papermill())
  File "/home/jb/.local/lib/python3.7/site-packages/click/core.py", line 1137, in __call__
    return self.main(*args, **kwargs)
  File "/home/jb/.local/lib/python3.7/site-packages/click/core.py", line 1062, in main
    rv = self.invoke(ctx)
  File "/home/jb/.local/lib/python3.7/site-packages/click/core.py", line 1404, in invoke
    return ctx.invoke(self.callback, **ctx.params)
  File "/home/jb/.local/lib/python3.7/site-packages/click/core.py", line 763, in invoke
    return __callback(*args, **kwargs)
  File "/home/jb/.local/lib/python3.7/site-packages/click/decorators.py", line 26, in new_func
    return f(get_current_context(), *args, **kwargs)
  File "/home/jb/.local/lib/python3.7/site-packages/papermill/cli.py", line 267, in papermill
    execution_timeout=execution_timeout,
  File "/home/jb/.local/lib/python3.7/site-packages/papermill/execute.py", line 122, in execute_notebook
    raise_for_execution_errors(nb, output_path)
  File "/home/jb/.local/lib/python3.7/site-packages/papermill/execute.py", line 234, in raise_for_execution_errors
    raise error
papermill.exceptions.PapermillExecutionError: 
---------------------------------------------------------------------------
Exception encountered at "In [18]":
---------------------------------------------------------------------------
TypeError                                 Traceback (most recent call last)
<ipython-input-18-d2153f43af6d> in <module>
     20             # The protocol version used is detected automatically, so we do not
     21             # have to specify it.
---> 22             sim_Countries_cname = pickle.load(f)
     23 
     24 

~/git/covid-19-sird/sim/output/src/simulation.py in <module>
     11 # run_model_set.cache_clear()
     12 
---> 13 import inputs
     14 
     15 

~/git/covid-19-sird/sim/output/src/inputs.py in <module>
    147 
    148 if dbg_scen:
--> 149     scenarios_ = scenarios_[:1]
    150 
    151 cc = ('{} '*len(countries_)).format(*countries_)

TypeError: unhashable type: 'slice'

 
CREATING COUNTRY COMPARISONS...
 
Input Notebook:  ./web-country-comp_.ipynb
Output Notebook: ./web-country-comp_.ipynb
Generating grammar tables from /home/jb/.local/lib/python3.7/site-packages/blib2to3/Grammar.txt
Writing grammar tables to /home/jb/.cache/black/20.8b1/Grammar3.7.3.final.0.pickle
Writing failed: [Errno 2] No such file or directory: '/home/jb/.cache/black/20.8b1/tmpxl_57og9'
Generating grammar tables from /home/jb/.local/lib/python3.7/site-packages/blib2to3/PatternGrammar.txt
Writing grammar tables to /home/jb/.cache/black/20.8b1/PatternGrammar3.7.3.final.0.pickle
Writing failed: [Errno 2] No such file or directory: '/home/jb/.cache/black/20.8b1/tmpcgb_oqpw'
Executing:   0%|          | 0/41 [00:00<?, ?cell/s]Executing notebook with kernel: python3
Executing:   2%|▏         | 1/41 [00:00<00:38,  1.05cell/s]Executing:  10%|▉         | 4/41 [00:01<00:25,  1.47cell/s]Executing:  12%|█▏        | 5/41 [00:01<00:19,  1.89cell/s]Executing:  17%|█▋        | 7/41 [00:01<00:13,  2.59cell/s]Executing:  24%|██▍       | 10/41 [00:01<00:08,  3.51cell/s]Executing:  29%|██▉       | 12/41 [00:02<00:11,  2.45cell/s]Executing:  32%|███▏      | 13/41 [00:03<00:09,  2.91cell/s]Executing:  34%|███▍      | 14/41 [00:03<00:08,  3.34cell/s]Executing:  37%|███▋      | 15/41 [00:03<00:06,  3.75cell/s]Executing:  39%|███▉      | 16/41 [00:03<00:06,  4.13cell/s]Executing:  41%|████▏     | 17/41 [00:03<00:05,  4.44cell/s]Executing:  44%|████▍     | 18/41 [00:04<00:04,  4.65cell/s]Executing:  46%|████▋     | 19/41 [00:04<00:04,  4.77cell/s]Executing:  49%|████▉     | 20/41 [00:04<00:04,  4.86cell/s]Executing:  51%|█████     | 21/41 [00:04<00:04,  4.16cell/s]Executing:  51%|█████     | 21/41 [00:05<00:04,  4.05cell/s]
Traceback (most recent call last):
  File "/home/jb/.local/bin/papermill", line 8, in <module>
    sys.exit(papermill())
  File "/home/jb/.local/lib/python3.7/site-packages/click/core.py", line 1137, in __call__
    return self.main(*args, **kwargs)
  File "/home/jb/.local/lib/python3.7/site-packages/click/core.py", line 1062, in main
    rv = self.invoke(ctx)
  File "/home/jb/.local/lib/python3.7/site-packages/click/core.py", line 1404, in invoke
    return ctx.invoke(self.callback, **ctx.params)
  File "/home/jb/.local/lib/python3.7/site-packages/click/core.py", line 763, in invoke
    return __callback(*args, **kwargs)
  File "/home/jb/.local/lib/python3.7/site-packages/click/decorators.py", line 26, in new_func
    return f(get_current_context(), *args, **kwargs)
  File "/home/jb/.local/lib/python3.7/site-packages/papermill/cli.py", line 267, in papermill
    execution_timeout=execution_timeout,
  File "/home/jb/.local/lib/python3.7/site-packages/papermill/execute.py", line 122, in execute_notebook
    raise_for_execution_errors(nb, output_path)
  File "/home/jb/.local/lib/python3.7/site-packages/papermill/execute.py", line 234, in raise_for_execution_errors
    raise error
papermill.exceptions.PapermillExecutionError: 
---------------------------------------------------------------------------
Exception encountered at "In [18]":
---------------------------------------------------------------------------
TypeError                                 Traceback (most recent call last)
<ipython-input-18-93c0b62bde6b> in <module>
     27             # The protocol version used is detected automatically, so we do not
     28             # have to specify it.
---> 29             sim_Countries_cname[c] = pickle.load(f)
     30 
     31 

~/git/covid-19-sird/sim/output/src/simulation.py in <module>
     11 # run_model_set.cache_clear()
     12 
---> 13 import inputs
     14 
     15 

~/git/covid-19-sird/sim/output/src/inputs.py in <module>
    147 
    148 if dbg_scen:
--> 149     scenarios_ = scenarios_[:1]
    150 
    151 cc = ('{} '*len(countries_)).format(*countries_)

TypeError: unhashable type: 'slice'

 
CREATING INDEX...
 
Input Notebook:  ./web-index_.ipynb
Output Notebook: ./web-index_.ipynb
Generating grammar tables from /home/jb/.local/lib/python3.7/site-packages/blib2to3/Grammar.txt
Writing grammar tables to /home/jb/.cache/black/20.8b1/Grammar3.7.3.final.0.pickle
Writing failed: [Errno 2] No such file or directory: '/home/jb/.cache/black/20.8b1/tmps726xs0o'
Generating grammar tables from /home/jb/.local/lib/python3.7/site-packages/blib2to3/PatternGrammar.txt
Writing grammar tables to /home/jb/.cache/black/20.8b1/PatternGrammar3.7.3.final.0.pickle
Writing failed: [Errno 2] No such file or directory: '/home/jb/.cache/black/20.8b1/tmp9irvkjgc'
Executing:   0%|          | 0/20 [00:00<?, ?cell/s]Executing notebook with kernel: python3
Executing:   5%|▌         | 1/20 [00:00<00:17,  1.11cell/s]Executing:  25%|██▌       | 5/20 [00:01<00:09,  1.56cell/s]Executing:  40%|████      | 8/20 [00:01<00:05,  2.18cell/s]Executing:  60%|██████    | 12/20 [00:01<00:02,  3.03cell/s]Executing:  80%|████████  | 16/20 [00:01<00:00,  4.16cell/s]Executing: 100%|██████████| 20/20 [00:01<00:00,  5.65cell/s]Executing: 100%|██████████| 20/20 [00:01<00:00, 11.07cell/s]
[NbConvertApp] Converting notebook web-index_.ipynb to notebook
[NbConvertApp] Writing 24930 bytes to web-index_.ipynb
[NbConvertApp] Converting notebook web-country-scen_.ipynb to notebook
[NbConvertApp] Writing 150639 bytes to web-country-scen_.ipynb
 
 
############################################################################
END OF ANALYSIS (WEB)
############################################################################
 
 
 
RUNTIME: 48 s (0 h)
 
